"""column error

Revision ID: 16323a4d83bf
Revises: 1cb8f382ebe3
Create Date: 2022-07-20 16:16:25.216407

"""
from alembic import op
import sqlalchemy as sa


# revision identifiers, used by Alembic.
revision = '16323a4d83bf'
down_revision = '1cb8f382ebe3'
branch_labels = None
depends_on = None


def upgrade():
    # ### commands auto generated by Alembic - please adjust! ###
    op.drop_table('user_idp_sp_app')
    # ### end Alembic commands ###


def downgrade():
    # ### commands auto generated by Alembic - please adjust! ###
    op.create_table('user_idp_sp_app',
    sa.Column('idp_users_id', sa.INTEGER(), autoincrement=False, nullable=True),
    sa.Column('sp_apps_id', sa.INTEGER(), autoincrement=False, nullable=True),
    sa.Column('is_accessible', sa.BOOLEAN(), autoincrement=False, nullable=False),
    sa.ForeignKeyConstraint(['idp_users_id'], ['idp_users.id'], name='user_idp_sp_app_idp_users_id_fkey'),
    sa.ForeignKeyConstraint(['sp_apps_id'], ['sp_apps.id'], name='user_idp_sp_app_sp_apps_id_fkey')
    )
    # ### end Alembic commands ###
